0036535152
================

=== UNARCHIVE AND STRUCTURE ===
OK!

=== COMPILE ===
Skipping (python)

=== EVALUATION ===

== BFS ==
  Passed 4 / 6 tests.

- Failed test: BFS
- Command run: python solution.py --ss 3x3_puzzle.txt --alg bfs
Execution timed out.

- Failed test: BFS
- Command run: python solution.py --ss ai.txt --alg bfs
Execution failed with error:
# BFS
Traceback (most recent call last):
  File "solution.py", line 155, in <module>
    main()
  File "solution.py", line 113, in main
    start_state, end_state, transitions = get_data(path_state)
  File "solution.py", line 21, in get_data
    city, transitions = line[0], line[1].split(" ")
IndexError: list index out of range


== UCS ==
  Passed 0 / 6 tests.

- Failed test: UCS
- Command run: python solution.py --ss 3x3_puzzle.txt --alg ucs
Execution timed out.

- Failed test: UCS
- Command run: python solution.py --ss ai.txt --alg ucs
Execution failed with error:
# UCS
Traceback (most recent call last):
  File "solution.py", line 155, in <module>
    main()
  File "solution.py", line 127, in main
    start_state, end_state, successors = get_data(path_state)
  File "solution.py", line 21, in get_data
    city, transitions = line[0], line[1].split(" ")
IndexError: list index out of range


- Failed test: UCS
- Command run: python solution.py --ss istra.txt --alg ucs
Mismatch with field: TOTAL_COST
-> Obtained output:
119.0
-> Expected output:
100.0
-> Complete obtained output:
# UCS
[FOUND_SOLUTION]: yes
[STATES_VISITED]: 14
[PATH_LENGTH]: 5
[TOTAL_COST]: 119.0
[PATH]: Pula => Barban => Labin => Lupoglav => Buzet
-> Complete expected output:
# UCS
[FOUND_SOLUTION]: yes
[STATES_VISITED]: 17
[PATH_LENGTH]: 5
[TOTAL_COST]: 100.0
[PATH]: Pula => Barban => Labin => Lupoglav => Buzet

- Failed test: UCS
- Command run: python solution.py --ss test_case_1.txt --alg ucs
Mismatch with field: TOTAL_COST
-> Obtained output:
305.0
-> Expected output:
54.0
-> Complete obtained output:
# UCS
[FOUND_SOLUTION]: yes
[STATES_VISITED]: 14
[PATH_LENGTH]: 5
[TOTAL_COST]: 305.0
[PATH]: A => D => H => E => O
-> Complete expected output:
# UCS
[FOUND_SOLUTION]: yes
[STATES_VISITED]: 14
[PATH_LENGTH]: 5
[TOTAL_COST]: 54.0
[PATH]: A => D => H => E => O

- Failed test: UCS
- Command run: python solution.py --ss test_case_2.txt --alg ucs
Mismatch with field: TOTAL_COST
-> Obtained output:
40.0
-> Expected output:
90.0
-> Complete obtained output:
# UCS
[FOUND_SOLUTION]: yes
[STATES_VISITED]: 11
[PATH_LENGTH]: 3
[TOTAL_COST]: 40.0
[PATH]: A => H => Z
-> Complete expected output:
# UCS
[FOUND_SOLUTION]: yes
[STATES_VISITED]: 21
[PATH_LENGTH]: 3
[TOTAL_COST]: 90.0
[PATH]: A => H => Z

- Failed test: UCS
- Command run: python solution.py --ss test_case_3.txt --alg ucs
Mismatch with field: TOTAL_COST
-> Obtained output:
322.0
-> Expected output:
208.0
-> Complete obtained output:
# UCS
[FOUND_SOLUTION]: yes
[STATES_VISITED]: 23
[PATH_LENGTH]: 6
[TOTAL_COST]: 322.0
[PATH]: A => E => F => S => D => Y
-> Complete expected output:
# UCS
[FOUND_SOLUTION]: yes
[STATES_VISITED]: 25
[PATH_LENGTH]: 7
[TOTAL_COST]: 208.0
[PATH]: A => E => F => G => M => B => Y

== A-STAR ==
  Passed 0 / 7 tests.

- Failed test: A-STAR ai_fail.txt
- Command run: python solution.py --ss ai.txt --alg astar --h ai_fail.txt
Execution failed with error:
# A-STAR ai_fail.txt
Traceback (most recent call last):
  File "solution.py", line 155, in <module>
    main()
  File "solution.py", line 143, in main
    start_state, end_state, successors = get_data(path_state)
  File "solution.py", line 21, in get_data
    city, transitions = line[0], line[1].split(" ")
IndexError: list index out of range


- Failed test: A-STAR ai_pass.txt
- Command run: python solution.py --ss ai.txt --alg astar --h ai_pass.txt
Execution failed with error:
# A-STAR ai_pass.txt
Traceback (most recent call last):
  File "solution.py", line 155, in <module>
    main()
  File "solution.py", line 143, in main
    start_state, end_state, successors = get_data(path_state)
  File "solution.py", line 21, in get_data
    city, transitions = line[0], line[1].split(" ")
IndexError: list index out of range


- Failed test: A-STAR istra_heuristic.txt
- Command run: python solution.py --ss istra.txt --alg astar --h istra_heuristic.txt
Execution failed with error:
# A-STAR istra_heuristic.txt
Traceback (most recent call last):
  File "solution.py", line 155, in <module>
    main()
  File "solution.py", line 146, in main
    print(f"[FOUND_SOLUTION]: {found_solution}")
UnboundLocalError: local variable 'found_solution' referenced before assignment


- Failed test: A-STAR istra_pessimistic_heuristic.txt
- Command run: python solution.py --ss istra.txt --alg astar --h istra_pessimistic_heuristic.txt
Execution failed with error:
# A-STAR istra_pessimistic_heuristic.txt
Traceback (most recent call last):
  File "solution.py", line 155, in <module>
    main()
  File "solution.py", line 146, in main
    print(f"[FOUND_SOLUTION]: {found_solution}")
UnboundLocalError: local variable 'found_solution' referenced before assignment


- Failed test: A-STAR test_case_1_heuristic.txt
- Command run: python solution.py --ss test_case_1.txt --alg astar --h test_case_1_heuristic.txt
Execution failed with error:
# A-STAR test_case_1_heuristic.txt
Traceback (most recent call last):
  File "solution.py", line 155, in <module>
    main()
  File "solution.py", line 146, in main
    print(f"[FOUND_SOLUTION]: {found_solution}")
UnboundLocalError: local variable 'found_solution' referenced before assignment


- Failed test: A-STAR test_case_2_heuristic.txt
- Command run: python solution.py --ss test_case_2.txt --alg astar --h test_case_2_heuristic.txt
Execution failed with error:
# A-STAR test_case_2_heuristic.txt
Traceback (most recent call last):
  File "solution.py", line 155, in <module>
    main()
  File "solution.py", line 146, in main
    print(f"[FOUND_SOLUTION]: {found_solution}")
UnboundLocalError: local variable 'found_solution' referenced before assignment


- Failed test: A-STAR test_case_3_heuristic.txt
- Command run: python solution.py --ss test_case_3.txt --alg astar --h test_case_3_heuristic.txt
Execution failed with error:
# A-STAR test_case_3_heuristic.txt
Traceback (most recent call last):
  File "solution.py", line 155, in <module>
    main()
  File "solution.py", line 146, in main
    print(f"[FOUND_SOLUTION]: {found_solution}")
UnboundLocalError: local variable 'found_solution' referenced before assignment


== HEURISTIC-CONSISTENT ==
  Passed 0 / 10 tests.

- Failed test: HEURISTIC-CONSISTENT ai_fail.txt
- Command run: python solution.py --ss ai.txt --h ai_fail.txt --check-consistent 
Execution failed with error:
Traceback (most recent call last):
  File "solution.py", line 155, in <module>
    main()
  File "solution.py", line 108, in main
    consistent = sys.argv[i+1]
IndexError: list index out of range


- Failed test: HEURISTIC-CONSISTENT ai_pass.txt
- Command run: python solution.py --ss ai.txt --h ai_pass.txt --check-consistent 
Execution failed with error:
Traceback (most recent call last):
  File "solution.py", line 155, in <module>
    main()
  File "solution.py", line 108, in main
    consistent = sys.argv[i+1]
IndexError: list index out of range


- Failed test: HEURISTIC-CONSISTENT istra_pessimistic_heuristic.txt
- Command run: python solution.py --ss istra.txt --h istra_pessimistic_heuristic.txt --check-consistent 
Execution failed with error:
Traceback (most recent call last):
  File "solution.py", line 155, in <module>
    main()
  File "solution.py", line 108, in main
    consistent = sys.argv[i+1]
IndexError: list index out of range


- Failed test: HEURISTIC-CONSISTENT istra_heuristic.txt
- Command run: python solution.py --ss istra.txt --h istra_heuristic.txt --check-consistent 
Execution failed with error:
Traceback (most recent call last):
  File "solution.py", line 155, in <module>
    main()
  File "solution.py", line 108, in main
    consistent = sys.argv[i+1]
IndexError: list index out of range


- Failed test: HEURISTIC-CONSISTENT test_case_1_heuristic.txt
- Command run: python solution.py --ss test_case_1.txt --h test_case_1_heuristic.txt --check-consistent 
Execution failed with error:
Traceback (most recent call last):
  File "solution.py", line 155, in <module>
    main()
  File "solution.py", line 108, in main
    consistent = sys.argv[i+1]
IndexError: list index out of range


- Failed test: HEURISTIC-CONSISTENT test_case_1_heuristic_nonopt.txt
- Command run: python solution.py --ss test_case_1.txt --h test_case_1_heuristic_nonopt.txt --check-consistent 
Execution failed with error:
Traceback (most recent call last):
  File "solution.py", line 155, in <module>
    main()
  File "solution.py", line 108, in main
    consistent = sys.argv[i+1]
IndexError: list index out of range


- Failed test: HEURISTIC-CONSISTENT test_case_2_heuristic.txt
- Command run: python solution.py --ss test_case_2.txt --h test_case_2_heuristic.txt --check-consistent 
Execution failed with error:
Traceback (most recent call last):
  File "solution.py", line 155, in <module>
    main()
  File "solution.py", line 108, in main
    consistent = sys.argv[i+1]
IndexError: list index out of range


- Failed test: HEURISTIC-CONSISTENT test_case_2_heuristic_nonopt.txt
- Command run: python solution.py --ss test_case_2.txt --h test_case_2_heuristic_nonopt.txt --check-consistent 
Execution failed with error:
Traceback (most recent call last):
  File "solution.py", line 155, in <module>
    main()
  File "solution.py", line 108, in main
    consistent = sys.argv[i+1]
IndexError: list index out of range


- Failed test: HEURISTIC-CONSISTENT test_case_3_heuristic.txt
- Command run: python solution.py --ss test_case_3.txt --h test_case_3_heuristic.txt --check-consistent 
Execution failed with error:
Traceback (most recent call last):
  File "solution.py", line 155, in <module>
    main()
  File "solution.py", line 108, in main
    consistent = sys.argv[i+1]
IndexError: list index out of range


- Failed test: HEURISTIC-CONSISTENT test_case_3_heuristic_nonopt.txt
- Command run: python solution.py --ss test_case_3.txt --h test_case_3_heuristic_nonopt.txt --check-consistent 
Execution failed with error:
Traceback (most recent call last):
  File "solution.py", line 155, in <module>
    main()
  File "solution.py", line 108, in main
    consistent = sys.argv[i+1]
IndexError: list index out of range


== HEURISTIC-OPTIMISTIC ==
  Passed 0 / 10 tests.

- Failed test: HEURISTIC-OPTIMISTIC ai_fail.txt
- Command run: python solution.py --ss ai.txt --h ai_fail.txt --check-optimistic 
Execution failed with error:
Traceback (most recent call last):
  File "solution.py", line 155, in <module>
    main()
  File "solution.py", line 106, in main
    optimistic = sys.argv[i+1]
IndexError: list index out of range


- Failed test: HEURISTIC-OPTIMISTIC ai_pass.txt
- Command run: python solution.py --ss ai.txt --h ai_pass.txt --check-optimistic 
Execution failed with error:
Traceback (most recent call last):
  File "solution.py", line 155, in <module>
    main()
  File "solution.py", line 106, in main
    optimistic = sys.argv[i+1]
IndexError: list index out of range


- Failed test: HEURISTIC-OPTIMISTIC istra_pessimistic_heuristic.txt
- Command run: python solution.py --ss istra.txt --h istra_pessimistic_heuristic.txt --check-optimistic 
Execution failed with error:
Traceback (most recent call last):
  File "solution.py", line 155, in <module>
    main()
  File "solution.py", line 106, in main
    optimistic = sys.argv[i+1]
IndexError: list index out of range


- Failed test: HEURISTIC-OPTIMISTIC istra_heuristic.txt
- Command run: python solution.py --ss istra.txt --h istra_heuristic.txt --check-optimistic 
Execution failed with error:
Traceback (most recent call last):
  File "solution.py", line 155, in <module>
    main()
  File "solution.py", line 106, in main
    optimistic = sys.argv[i+1]
IndexError: list index out of range


- Failed test: HEURISTIC-OPTIMISTIC test_case_1_heuristic.txt
- Command run: python solution.py --ss test_case_1.txt --h test_case_1_heuristic.txt --check-optimistic 
Execution failed with error:
Traceback (most recent call last):
  File "solution.py", line 155, in <module>
    main()
  File "solution.py", line 106, in main
    optimistic = sys.argv[i+1]
IndexError: list index out of range


- Failed test: HEURISTIC-OPTIMISTIC test_case_1_heuristic_nonopt.txt
- Command run: python solution.py --ss test_case_1.txt --h test_case_1_heuristic_nonopt.txt --check-optimistic 
Execution failed with error:
Traceback (most recent call last):
  File "solution.py", line 155, in <module>
    main()
  File "solution.py", line 106, in main
    optimistic = sys.argv[i+1]
IndexError: list index out of range


- Failed test: HEURISTIC-OPTIMISTIC test_case_2_heuristic.txt
- Command run: python solution.py --ss test_case_2.txt --h test_case_2_heuristic.txt --check-optimistic 
Execution failed with error:
Traceback (most recent call last):
  File "solution.py", line 155, in <module>
    main()
  File "solution.py", line 106, in main
    optimistic = sys.argv[i+1]
IndexError: list index out of range


- Failed test: HEURISTIC-OPTIMISTIC test_case_2_heuristic_nonopt.txt
- Command run: python solution.py --ss test_case_2.txt --h test_case_2_heuristic_nonopt.txt --check-optimistic 
Execution failed with error:
Traceback (most recent call last):
  File "solution.py", line 155, in <module>
    main()
  File "solution.py", line 106, in main
    optimistic = sys.argv[i+1]
IndexError: list index out of range


- Failed test: HEURISTIC-OPTIMISTIC test_case_3_heuristic.txt
- Command run: python solution.py --ss test_case_3.txt --h test_case_3_heuristic.txt --check-optimistic 
Execution failed with error:
Traceback (most recent call last):
  File "solution.py", line 155, in <module>
    main()
  File "solution.py", line 106, in main
    optimistic = sys.argv[i+1]
IndexError: list index out of range


- Failed test: HEURISTIC-OPTIMISTIC test_case_3_heuristic_nonopt.txt
- Command run: python solution.py --ss test_case_3.txt --h test_case_3_heuristic_nonopt.txt --check-optimistic 
Execution failed with error:
Traceback (most recent call last):
  File "solution.py", line 155, in <module>
    main()
  File "solution.py", line 106, in main
    optimistic = sys.argv[i+1]
IndexError: list index out of range


=== TOTAL RESULTS ===
4 / 39 tests passed. (10.26%)

