0036535152
================

=== UNARCHIVE AND STRUCTURE ===
OK!

=== COMPILE ===
Skipping (python)

=== EVALUATION ===

== BFS ==
  Passed 5 / 6 tests.

- Failed test: BFS
- Command run: python solution.py --ss 3x3_puzzle.txt --alg bfs
Execution timed out.

== UCS ==
  Passed 5 / 6 tests.

- Failed test: UCS
- Command run: python solution.py --ss 3x3_puzzle.txt --alg ucs
Execution timed out.

== A-STAR ==
  Passed 0 / 7 tests.

- Failed test: A-STAR ai_fail.txt
- Command run: python solution.py --ss ai.txt --alg astar --h ai_fail.txt
Execution failed with error:
# A-STAR ai_fail.txt
Traceback (most recent call last):
  File "C:\Users\Mateo\AppData\Local\Temp\tmp4o1wvxfb\lab1py\solution.py", line 193, in <module>
    main()
  File "C:\Users\Mateo\AppData\Local\Temp\tmp4o1wvxfb\lab1py\solution.py", line 183, in main
    print(f"[FOUND_SOLUTION]: {found_solution}")
          ^^^^^^^^^^^^^^^^^^^^^^^^^^^^^^^^^^^^^
UnboundLocalError: cannot access local variable 'found_solution' where it is not associated with a value


- Failed test: A-STAR ai_pass.txt
- Command run: python solution.py --ss ai.txt --alg astar --h ai_pass.txt
Execution failed with error:
# A-STAR ai_pass.txt
Traceback (most recent call last):
  File "C:\Users\Mateo\AppData\Local\Temp\tmp4o1wvxfb\lab1py\solution.py", line 193, in <module>
    main()
  File "C:\Users\Mateo\AppData\Local\Temp\tmp4o1wvxfb\lab1py\solution.py", line 183, in main
    print(f"[FOUND_SOLUTION]: {found_solution}")
          ^^^^^^^^^^^^^^^^^^^^^^^^^^^^^^^^^^^^^
UnboundLocalError: cannot access local variable 'found_solution' where it is not associated with a value


- Failed test: A-STAR istra_heuristic.txt
- Command run: python solution.py --ss istra.txt --alg astar --h istra_heuristic.txt
Execution failed with error:
# A-STAR istra_heuristic.txt
Traceback (most recent call last):
  File "C:\Users\Mateo\AppData\Local\Temp\tmp4o1wvxfb\lab1py\solution.py", line 193, in <module>
    main()
  File "C:\Users\Mateo\AppData\Local\Temp\tmp4o1wvxfb\lab1py\solution.py", line 183, in main
    print(f"[FOUND_SOLUTION]: {found_solution}")
          ^^^^^^^^^^^^^^^^^^^^^^^^^^^^^^^^^^^^^
UnboundLocalError: cannot access local variable 'found_solution' where it is not associated with a value


- Failed test: A-STAR istra_pessimistic_heuristic.txt
- Command run: python solution.py --ss istra.txt --alg astar --h istra_pessimistic_heuristic.txt
Execution failed with error:
# A-STAR istra_pessimistic_heuristic.txt
Traceback (most recent call last):
  File "C:\Users\Mateo\AppData\Local\Temp\tmp4o1wvxfb\lab1py\solution.py", line 193, in <module>
    main()
  File "C:\Users\Mateo\AppData\Local\Temp\tmp4o1wvxfb\lab1py\solution.py", line 183, in main
    print(f"[FOUND_SOLUTION]: {found_solution}")
          ^^^^^^^^^^^^^^^^^^^^^^^^^^^^^^^^^^^^^
UnboundLocalError: cannot access local variable 'found_solution' where it is not associated with a value


- Failed test: A-STAR test_case_1_heuristic.txt
- Command run: python solution.py --ss test_case_1.txt --alg astar --h test_case_1_heuristic.txt
Execution failed with error:
# A-STAR test_case_1_heuristic.txt
Traceback (most recent call last):
  File "C:\Users\Mateo\AppData\Local\Temp\tmp4o1wvxfb\lab1py\solution.py", line 193, in <module>
    main()
  File "C:\Users\Mateo\AppData\Local\Temp\tmp4o1wvxfb\lab1py\solution.py", line 183, in main
    print(f"[FOUND_SOLUTION]: {found_solution}")
          ^^^^^^^^^^^^^^^^^^^^^^^^^^^^^^^^^^^^^
UnboundLocalError: cannot access local variable 'found_solution' where it is not associated with a value


- Failed test: A-STAR test_case_2_heuristic.txt
- Command run: python solution.py --ss test_case_2.txt --alg astar --h test_case_2_heuristic.txt
Execution failed with error:
# A-STAR test_case_2_heuristic.txt
Traceback (most recent call last):
  File "C:\Users\Mateo\AppData\Local\Temp\tmp4o1wvxfb\lab1py\solution.py", line 193, in <module>
    main()
  File "C:\Users\Mateo\AppData\Local\Temp\tmp4o1wvxfb\lab1py\solution.py", line 183, in main
    print(f"[FOUND_SOLUTION]: {found_solution}")
          ^^^^^^^^^^^^^^^^^^^^^^^^^^^^^^^^^^^^^
UnboundLocalError: cannot access local variable 'found_solution' where it is not associated with a value


- Failed test: A-STAR test_case_3_heuristic.txt
- Command run: python solution.py --ss test_case_3.txt --alg astar --h test_case_3_heuristic.txt
Execution failed with error:
# A-STAR test_case_3_heuristic.txt
Traceback (most recent call last):
  File "C:\Users\Mateo\AppData\Local\Temp\tmp4o1wvxfb\lab1py\solution.py", line 193, in <module>
    main()
  File "C:\Users\Mateo\AppData\Local\Temp\tmp4o1wvxfb\lab1py\solution.py", line 183, in main
    print(f"[FOUND_SOLUTION]: {found_solution}")
          ^^^^^^^^^^^^^^^^^^^^^^^^^^^^^^^^^^^^^
UnboundLocalError: cannot access local variable 'found_solution' where it is not associated with a value


== HEURISTIC-CONSISTENT ==
  Passed 0 / 10 tests.

- Failed test: HEURISTIC-CONSISTENT ai_fail.txt
- Command run: python solution.py --ss ai.txt --h ai_fail.txt --check-consistent 
Execution failed with error:
Traceback (most recent call last):
  File "C:\Users\Mateo\AppData\Local\Temp\tmp4o1wvxfb\lab1py\solution.py", line 193, in <module>
    main()
  File "C:\Users\Mateo\AppData\Local\Temp\tmp4o1wvxfb\lab1py\solution.py", line 145, in main
    consistent = sys.argv[i+1]
                 ~~~~~~~~^^^^^
IndexError: list index out of range


- Failed test: HEURISTIC-CONSISTENT ai_pass.txt
- Command run: python solution.py --ss ai.txt --h ai_pass.txt --check-consistent 
Execution failed with error:
Traceback (most recent call last):
  File "C:\Users\Mateo\AppData\Local\Temp\tmp4o1wvxfb\lab1py\solution.py", line 193, in <module>
    main()
  File "C:\Users\Mateo\AppData\Local\Temp\tmp4o1wvxfb\lab1py\solution.py", line 145, in main
    consistent = sys.argv[i+1]
                 ~~~~~~~~^^^^^
IndexError: list index out of range


- Failed test: HEURISTIC-CONSISTENT istra_pessimistic_heuristic.txt
- Command run: python solution.py --ss istra.txt --h istra_pessimistic_heuristic.txt --check-consistent 
Execution failed with error:
Traceback (most recent call last):
  File "C:\Users\Mateo\AppData\Local\Temp\tmp4o1wvxfb\lab1py\solution.py", line 193, in <module>
    main()
  File "C:\Users\Mateo\AppData\Local\Temp\tmp4o1wvxfb\lab1py\solution.py", line 145, in main
    consistent = sys.argv[i+1]
                 ~~~~~~~~^^^^^
IndexError: list index out of range


- Failed test: HEURISTIC-CONSISTENT istra_heuristic.txt
- Command run: python solution.py --ss istra.txt --h istra_heuristic.txt --check-consistent 
Execution failed with error:
Traceback (most recent call last):
  File "C:\Users\Mateo\AppData\Local\Temp\tmp4o1wvxfb\lab1py\solution.py", line 193, in <module>
    main()
  File "C:\Users\Mateo\AppData\Local\Temp\tmp4o1wvxfb\lab1py\solution.py", line 145, in main
    consistent = sys.argv[i+1]
                 ~~~~~~~~^^^^^
IndexError: list index out of range


- Failed test: HEURISTIC-CONSISTENT test_case_1_heuristic.txt
- Command run: python solution.py --ss test_case_1.txt --h test_case_1_heuristic.txt --check-consistent 
Execution failed with error:
Traceback (most recent call last):
  File "C:\Users\Mateo\AppData\Local\Temp\tmp4o1wvxfb\lab1py\solution.py", line 193, in <module>
    main()
  File "C:\Users\Mateo\AppData\Local\Temp\tmp4o1wvxfb\lab1py\solution.py", line 145, in main
    consistent = sys.argv[i+1]
                 ~~~~~~~~^^^^^
IndexError: list index out of range


- Failed test: HEURISTIC-CONSISTENT test_case_1_heuristic_nonopt.txt
- Command run: python solution.py --ss test_case_1.txt --h test_case_1_heuristic_nonopt.txt --check-consistent 
Execution failed with error:
Traceback (most recent call last):
  File "C:\Users\Mateo\AppData\Local\Temp\tmp4o1wvxfb\lab1py\solution.py", line 193, in <module>
    main()
  File "C:\Users\Mateo\AppData\Local\Temp\tmp4o1wvxfb\lab1py\solution.py", line 145, in main
    consistent = sys.argv[i+1]
                 ~~~~~~~~^^^^^
IndexError: list index out of range


- Failed test: HEURISTIC-CONSISTENT test_case_2_heuristic.txt
- Command run: python solution.py --ss test_case_2.txt --h test_case_2_heuristic.txt --check-consistent 
Execution failed with error:
Traceback (most recent call last):
  File "C:\Users\Mateo\AppData\Local\Temp\tmp4o1wvxfb\lab1py\solution.py", line 193, in <module>
    main()
  File "C:\Users\Mateo\AppData\Local\Temp\tmp4o1wvxfb\lab1py\solution.py", line 145, in main
    consistent = sys.argv[i+1]
                 ~~~~~~~~^^^^^
IndexError: list index out of range


- Failed test: HEURISTIC-CONSISTENT test_case_2_heuristic_nonopt.txt
- Command run: python solution.py --ss test_case_2.txt --h test_case_2_heuristic_nonopt.txt --check-consistent 
Execution failed with error:
Traceback (most recent call last):
  File "C:\Users\Mateo\AppData\Local\Temp\tmp4o1wvxfb\lab1py\solution.py", line 193, in <module>
    main()
  File "C:\Users\Mateo\AppData\Local\Temp\tmp4o1wvxfb\lab1py\solution.py", line 145, in main
    consistent = sys.argv[i+1]
                 ~~~~~~~~^^^^^
IndexError: list index out of range


- Failed test: HEURISTIC-CONSISTENT test_case_3_heuristic.txt
- Command run: python solution.py --ss test_case_3.txt --h test_case_3_heuristic.txt --check-consistent 
Execution failed with error:
Traceback (most recent call last):
  File "C:\Users\Mateo\AppData\Local\Temp\tmp4o1wvxfb\lab1py\solution.py", line 193, in <module>
    main()
  File "C:\Users\Mateo\AppData\Local\Temp\tmp4o1wvxfb\lab1py\solution.py", line 145, in main
    consistent = sys.argv[i+1]
                 ~~~~~~~~^^^^^
IndexError: list index out of range


- Failed test: HEURISTIC-CONSISTENT test_case_3_heuristic_nonopt.txt
- Command run: python solution.py --ss test_case_3.txt --h test_case_3_heuristic_nonopt.txt --check-consistent 
Execution failed with error:
Traceback (most recent call last):
  File "C:\Users\Mateo\AppData\Local\Temp\tmp4o1wvxfb\lab1py\solution.py", line 193, in <module>
    main()
  File "C:\Users\Mateo\AppData\Local\Temp\tmp4o1wvxfb\lab1py\solution.py", line 145, in main
    consistent = sys.argv[i+1]
                 ~~~~~~~~^^^^^
IndexError: list index out of range


== HEURISTIC-OPTIMISTIC ==
  Passed 0 / 10 tests.

- Failed test: HEURISTIC-OPTIMISTIC ai_fail.txt
- Command run: python solution.py --ss ai.txt --h ai_fail.txt --check-optimistic 
Execution failed with error:
Traceback (most recent call last):
  File "C:\Users\Mateo\AppData\Local\Temp\tmp4o1wvxfb\lab1py\solution.py", line 193, in <module>
    main()
  File "C:\Users\Mateo\AppData\Local\Temp\tmp4o1wvxfb\lab1py\solution.py", line 143, in main
    optimistic = sys.argv[i+1]
                 ~~~~~~~~^^^^^
IndexError: list index out of range


- Failed test: HEURISTIC-OPTIMISTIC ai_pass.txt
- Command run: python solution.py --ss ai.txt --h ai_pass.txt --check-optimistic 
Execution failed with error:
Traceback (most recent call last):
  File "C:\Users\Mateo\AppData\Local\Temp\tmp4o1wvxfb\lab1py\solution.py", line 193, in <module>
    main()
  File "C:\Users\Mateo\AppData\Local\Temp\tmp4o1wvxfb\lab1py\solution.py", line 143, in main
    optimistic = sys.argv[i+1]
                 ~~~~~~~~^^^^^
IndexError: list index out of range


- Failed test: HEURISTIC-OPTIMISTIC istra_pessimistic_heuristic.txt
- Command run: python solution.py --ss istra.txt --h istra_pessimistic_heuristic.txt --check-optimistic 
Execution failed with error:
Traceback (most recent call last):
  File "C:\Users\Mateo\AppData\Local\Temp\tmp4o1wvxfb\lab1py\solution.py", line 193, in <module>
    main()
  File "C:\Users\Mateo\AppData\Local\Temp\tmp4o1wvxfb\lab1py\solution.py", line 143, in main
    optimistic = sys.argv[i+1]
                 ~~~~~~~~^^^^^
IndexError: list index out of range


- Failed test: HEURISTIC-OPTIMISTIC istra_heuristic.txt
- Command run: python solution.py --ss istra.txt --h istra_heuristic.txt --check-optimistic 
Execution failed with error:
Traceback (most recent call last):
  File "C:\Users\Mateo\AppData\Local\Temp\tmp4o1wvxfb\lab1py\solution.py", line 193, in <module>
    main()
  File "C:\Users\Mateo\AppData\Local\Temp\tmp4o1wvxfb\lab1py\solution.py", line 143, in main
    optimistic = sys.argv[i+1]
                 ~~~~~~~~^^^^^
IndexError: list index out of range


- Failed test: HEURISTIC-OPTIMISTIC test_case_1_heuristic.txt
- Command run: python solution.py --ss test_case_1.txt --h test_case_1_heuristic.txt --check-optimistic 
Execution failed with error:
Traceback (most recent call last):
  File "C:\Users\Mateo\AppData\Local\Temp\tmp4o1wvxfb\lab1py\solution.py", line 193, in <module>
    main()
  File "C:\Users\Mateo\AppData\Local\Temp\tmp4o1wvxfb\lab1py\solution.py", line 143, in main
    optimistic = sys.argv[i+1]
                 ~~~~~~~~^^^^^
IndexError: list index out of range


- Failed test: HEURISTIC-OPTIMISTIC test_case_1_heuristic_nonopt.txt
- Command run: python solution.py --ss test_case_1.txt --h test_case_1_heuristic_nonopt.txt --check-optimistic 
Execution failed with error:
Traceback (most recent call last):
  File "C:\Users\Mateo\AppData\Local\Temp\tmp4o1wvxfb\lab1py\solution.py", line 193, in <module>
    main()
  File "C:\Users\Mateo\AppData\Local\Temp\tmp4o1wvxfb\lab1py\solution.py", line 143, in main
    optimistic = sys.argv[i+1]
                 ~~~~~~~~^^^^^
IndexError: list index out of range


- Failed test: HEURISTIC-OPTIMISTIC test_case_2_heuristic.txt
- Command run: python solution.py --ss test_case_2.txt --h test_case_2_heuristic.txt --check-optimistic 
Execution failed with error:
Traceback (most recent call last):
  File "C:\Users\Mateo\AppData\Local\Temp\tmp4o1wvxfb\lab1py\solution.py", line 193, in <module>
    main()
  File "C:\Users\Mateo\AppData\Local\Temp\tmp4o1wvxfb\lab1py\solution.py", line 143, in main
    optimistic = sys.argv[i+1]
                 ~~~~~~~~^^^^^
IndexError: list index out of range


- Failed test: HEURISTIC-OPTIMISTIC test_case_2_heuristic_nonopt.txt
- Command run: python solution.py --ss test_case_2.txt --h test_case_2_heuristic_nonopt.txt --check-optimistic 
Execution failed with error:
Traceback (most recent call last):
  File "C:\Users\Mateo\AppData\Local\Temp\tmp4o1wvxfb\lab1py\solution.py", line 193, in <module>
    main()
  File "C:\Users\Mateo\AppData\Local\Temp\tmp4o1wvxfb\lab1py\solution.py", line 143, in main
    optimistic = sys.argv[i+1]
                 ~~~~~~~~^^^^^
IndexError: list index out of range


- Failed test: HEURISTIC-OPTIMISTIC test_case_3_heuristic.txt
- Command run: python solution.py --ss test_case_3.txt --h test_case_3_heuristic.txt --check-optimistic 
Execution failed with error:
Traceback (most recent call last):
  File "C:\Users\Mateo\AppData\Local\Temp\tmp4o1wvxfb\lab1py\solution.py", line 193, in <module>
    main()
  File "C:\Users\Mateo\AppData\Local\Temp\tmp4o1wvxfb\lab1py\solution.py", line 143, in main
    optimistic = sys.argv[i+1]
                 ~~~~~~~~^^^^^
IndexError: list index out of range


- Failed test: HEURISTIC-OPTIMISTIC test_case_3_heuristic_nonopt.txt
- Command run: python solution.py --ss test_case_3.txt --h test_case_3_heuristic_nonopt.txt --check-optimistic 
Execution failed with error:
Traceback (most recent call last):
  File "C:\Users\Mateo\AppData\Local\Temp\tmp4o1wvxfb\lab1py\solution.py", line 193, in <module>
    main()
  File "C:\Users\Mateo\AppData\Local\Temp\tmp4o1wvxfb\lab1py\solution.py", line 143, in main
    optimistic = sys.argv[i+1]
                 ~~~~~~~~^^^^^
IndexError: list index out of range


=== TOTAL RESULTS ===
10 / 39 tests passed. (25.64%)

