0036535152
================

=== UNARCHIVE AND STRUCTURE ===
OK!

=== COMPILE ===
Skipping (python)

=== EVALUATION ===

== BFS ==
  Passed 6 / 6 tests.

== UCS ==
  Passed 6 / 6 tests.

== A-STAR ==
  Passed 6 / 7 tests.

- Failed test: A-STAR istra_pessimistic_heuristic.txt
- Command run: python solution.py --ss istra.txt --alg astar --h istra_pessimistic_heuristic.txt
Mismatch with field: TOTAL_COST
-> Obtained output:
100.0
-> Expected output:
102.0
-> Complete obtained output:
# A-STAR istra_pessimistic_heuristic.txt
[FOUND_SOLUTION]: yes
[STATES_VISITED]: 14
[PATH_LENGTH]: 5
[TOTAL_COST]: 100.0
[PATH]: Pula => Barban => Labin => Lupoglav => Buzet
-> Complete expected output:
# A-STAR istra_pessimistic_heuristic.txt
[FOUND_SOLUTION]: yes
[STATES_VISITED]: 13
[PATH_LENGTH]: 7
[TOTAL_COST]: 102.0
[PATH]: Pula => Vodnjan => Kanfanar => Å½minj => Pazin => Motovun => Buzet

== HEURISTIC-CONSISTENT ==
  Passed 0 / 10 tests.

- Failed test: HEURISTIC-CONSISTENT ai_fail.txt
- Command run: python solution.py --ss ai.txt --h ai_fail.txt --check-consistent 
Execution failed with error:
Traceback (most recent call last):
  File "C:\Users\Mateo\AppData\Local\Temp\tmpga3kpq40\lab1py\solution.py", line 241, in <module>
    main()
  File "C:\Users\Mateo\AppData\Local\Temp\tmpga3kpq40\lab1py\solution.py", line 193, in main
    consistent = sys.argv[i+1]
                 ~~~~~~~~^^^^^
IndexError: list index out of range


- Failed test: HEURISTIC-CONSISTENT ai_pass.txt
- Command run: python solution.py --ss ai.txt --h ai_pass.txt --check-consistent 
Execution failed with error:
Traceback (most recent call last):
  File "C:\Users\Mateo\AppData\Local\Temp\tmpga3kpq40\lab1py\solution.py", line 241, in <module>
    main()
  File "C:\Users\Mateo\AppData\Local\Temp\tmpga3kpq40\lab1py\solution.py", line 193, in main
    consistent = sys.argv[i+1]
                 ~~~~~~~~^^^^^
IndexError: list index out of range


- Failed test: HEURISTIC-CONSISTENT istra_pessimistic_heuristic.txt
- Command run: python solution.py --ss istra.txt --h istra_pessimistic_heuristic.txt --check-consistent 
Execution failed with error:
Traceback (most recent call last):
  File "C:\Users\Mateo\AppData\Local\Temp\tmpga3kpq40\lab1py\solution.py", line 241, in <module>
    main()
  File "C:\Users\Mateo\AppData\Local\Temp\tmpga3kpq40\lab1py\solution.py", line 193, in main
    consistent = sys.argv[i+1]
                 ~~~~~~~~^^^^^
IndexError: list index out of range


- Failed test: HEURISTIC-CONSISTENT istra_heuristic.txt
- Command run: python solution.py --ss istra.txt --h istra_heuristic.txt --check-consistent 
Execution failed with error:
Traceback (most recent call last):
  File "C:\Users\Mateo\AppData\Local\Temp\tmpga3kpq40\lab1py\solution.py", line 241, in <module>
    main()
  File "C:\Users\Mateo\AppData\Local\Temp\tmpga3kpq40\lab1py\solution.py", line 193, in main
    consistent = sys.argv[i+1]
                 ~~~~~~~~^^^^^
IndexError: list index out of range


- Failed test: HEURISTIC-CONSISTENT test_case_1_heuristic.txt
- Command run: python solution.py --ss test_case_1.txt --h test_case_1_heuristic.txt --check-consistent 
Execution failed with error:
Traceback (most recent call last):
  File "C:\Users\Mateo\AppData\Local\Temp\tmpga3kpq40\lab1py\solution.py", line 241, in <module>
    main()
  File "C:\Users\Mateo\AppData\Local\Temp\tmpga3kpq40\lab1py\solution.py", line 193, in main
    consistent = sys.argv[i+1]
                 ~~~~~~~~^^^^^
IndexError: list index out of range


- Failed test: HEURISTIC-CONSISTENT test_case_1_heuristic_nonopt.txt
- Command run: python solution.py --ss test_case_1.txt --h test_case_1_heuristic_nonopt.txt --check-consistent 
Execution failed with error:
Traceback (most recent call last):
  File "C:\Users\Mateo\AppData\Local\Temp\tmpga3kpq40\lab1py\solution.py", line 241, in <module>
    main()
  File "C:\Users\Mateo\AppData\Local\Temp\tmpga3kpq40\lab1py\solution.py", line 193, in main
    consistent = sys.argv[i+1]
                 ~~~~~~~~^^^^^
IndexError: list index out of range


- Failed test: HEURISTIC-CONSISTENT test_case_2_heuristic.txt
- Command run: python solution.py --ss test_case_2.txt --h test_case_2_heuristic.txt --check-consistent 
Execution failed with error:
Traceback (most recent call last):
  File "C:\Users\Mateo\AppData\Local\Temp\tmpga3kpq40\lab1py\solution.py", line 241, in <module>
    main()
  File "C:\Users\Mateo\AppData\Local\Temp\tmpga3kpq40\lab1py\solution.py", line 193, in main
    consistent = sys.argv[i+1]
                 ~~~~~~~~^^^^^
IndexError: list index out of range


- Failed test: HEURISTIC-CONSISTENT test_case_2_heuristic_nonopt.txt
- Command run: python solution.py --ss test_case_2.txt --h test_case_2_heuristic_nonopt.txt --check-consistent 
Execution failed with error:
Traceback (most recent call last):
  File "C:\Users\Mateo\AppData\Local\Temp\tmpga3kpq40\lab1py\solution.py", line 241, in <module>
    main()
  File "C:\Users\Mateo\AppData\Local\Temp\tmpga3kpq40\lab1py\solution.py", line 193, in main
    consistent = sys.argv[i+1]
                 ~~~~~~~~^^^^^
IndexError: list index out of range


- Failed test: HEURISTIC-CONSISTENT test_case_3_heuristic.txt
- Command run: python solution.py --ss test_case_3.txt --h test_case_3_heuristic.txt --check-consistent 
Execution failed with error:
Traceback (most recent call last):
  File "C:\Users\Mateo\AppData\Local\Temp\tmpga3kpq40\lab1py\solution.py", line 241, in <module>
    main()
  File "C:\Users\Mateo\AppData\Local\Temp\tmpga3kpq40\lab1py\solution.py", line 193, in main
    consistent = sys.argv[i+1]
                 ~~~~~~~~^^^^^
IndexError: list index out of range


- Failed test: HEURISTIC-CONSISTENT test_case_3_heuristic_nonopt.txt
- Command run: python solution.py --ss test_case_3.txt --h test_case_3_heuristic_nonopt.txt --check-consistent 
Execution failed with error:
Traceback (most recent call last):
  File "C:\Users\Mateo\AppData\Local\Temp\tmpga3kpq40\lab1py\solution.py", line 241, in <module>
    main()
  File "C:\Users\Mateo\AppData\Local\Temp\tmpga3kpq40\lab1py\solution.py", line 193, in main
    consistent = sys.argv[i+1]
                 ~~~~~~~~^^^^^
IndexError: list index out of range


== HEURISTIC-OPTIMISTIC ==
  Passed 0 / 10 tests.

- Failed test: HEURISTIC-OPTIMISTIC ai_fail.txt
- Command run: python solution.py --ss ai.txt --h ai_fail.txt --check-optimistic 
Execution failed with error:
Traceback (most recent call last):
  File "C:\Users\Mateo\AppData\Local\Temp\tmpga3kpq40\lab1py\solution.py", line 241, in <module>
    main()
  File "C:\Users\Mateo\AppData\Local\Temp\tmpga3kpq40\lab1py\solution.py", line 191, in main
    optimistic = sys.argv[i+1]
                 ~~~~~~~~^^^^^
IndexError: list index out of range


- Failed test: HEURISTIC-OPTIMISTIC ai_pass.txt
- Command run: python solution.py --ss ai.txt --h ai_pass.txt --check-optimistic 
Execution failed with error:
Traceback (most recent call last):
  File "C:\Users\Mateo\AppData\Local\Temp\tmpga3kpq40\lab1py\solution.py", line 241, in <module>
    main()
  File "C:\Users\Mateo\AppData\Local\Temp\tmpga3kpq40\lab1py\solution.py", line 191, in main
    optimistic = sys.argv[i+1]
                 ~~~~~~~~^^^^^
IndexError: list index out of range


- Failed test: HEURISTIC-OPTIMISTIC istra_pessimistic_heuristic.txt
- Command run: python solution.py --ss istra.txt --h istra_pessimistic_heuristic.txt --check-optimistic 
Execution failed with error:
Traceback (most recent call last):
  File "C:\Users\Mateo\AppData\Local\Temp\tmpga3kpq40\lab1py\solution.py", line 241, in <module>
    main()
  File "C:\Users\Mateo\AppData\Local\Temp\tmpga3kpq40\lab1py\solution.py", line 191, in main
    optimistic = sys.argv[i+1]
                 ~~~~~~~~^^^^^
IndexError: list index out of range


- Failed test: HEURISTIC-OPTIMISTIC istra_heuristic.txt
- Command run: python solution.py --ss istra.txt --h istra_heuristic.txt --check-optimistic 
Execution failed with error:
Traceback (most recent call last):
  File "C:\Users\Mateo\AppData\Local\Temp\tmpga3kpq40\lab1py\solution.py", line 241, in <module>
    main()
  File "C:\Users\Mateo\AppData\Local\Temp\tmpga3kpq40\lab1py\solution.py", line 191, in main
    optimistic = sys.argv[i+1]
                 ~~~~~~~~^^^^^
IndexError: list index out of range


- Failed test: HEURISTIC-OPTIMISTIC test_case_1_heuristic.txt
- Command run: python solution.py --ss test_case_1.txt --h test_case_1_heuristic.txt --check-optimistic 
Execution failed with error:
Traceback (most recent call last):
  File "C:\Users\Mateo\AppData\Local\Temp\tmpga3kpq40\lab1py\solution.py", line 241, in <module>
    main()
  File "C:\Users\Mateo\AppData\Local\Temp\tmpga3kpq40\lab1py\solution.py", line 191, in main
    optimistic = sys.argv[i+1]
                 ~~~~~~~~^^^^^
IndexError: list index out of range


- Failed test: HEURISTIC-OPTIMISTIC test_case_1_heuristic_nonopt.txt
- Command run: python solution.py --ss test_case_1.txt --h test_case_1_heuristic_nonopt.txt --check-optimistic 
Execution failed with error:
Traceback (most recent call last):
  File "C:\Users\Mateo\AppData\Local\Temp\tmpga3kpq40\lab1py\solution.py", line 241, in <module>
    main()
  File "C:\Users\Mateo\AppData\Local\Temp\tmpga3kpq40\lab1py\solution.py", line 191, in main
    optimistic = sys.argv[i+1]
                 ~~~~~~~~^^^^^
IndexError: list index out of range


- Failed test: HEURISTIC-OPTIMISTIC test_case_2_heuristic.txt
- Command run: python solution.py --ss test_case_2.txt --h test_case_2_heuristic.txt --check-optimistic 
Execution failed with error:
Traceback (most recent call last):
  File "C:\Users\Mateo\AppData\Local\Temp\tmpga3kpq40\lab1py\solution.py", line 241, in <module>
    main()
  File "C:\Users\Mateo\AppData\Local\Temp\tmpga3kpq40\lab1py\solution.py", line 191, in main
    optimistic = sys.argv[i+1]
                 ~~~~~~~~^^^^^
IndexError: list index out of range


- Failed test: HEURISTIC-OPTIMISTIC test_case_2_heuristic_nonopt.txt
- Command run: python solution.py --ss test_case_2.txt --h test_case_2_heuristic_nonopt.txt --check-optimistic 
Execution failed with error:
Traceback (most recent call last):
  File "C:\Users\Mateo\AppData\Local\Temp\tmpga3kpq40\lab1py\solution.py", line 241, in <module>
    main()
  File "C:\Users\Mateo\AppData\Local\Temp\tmpga3kpq40\lab1py\solution.py", line 191, in main
    optimistic = sys.argv[i+1]
                 ~~~~~~~~^^^^^
IndexError: list index out of range


- Failed test: HEURISTIC-OPTIMISTIC test_case_3_heuristic.txt
- Command run: python solution.py --ss test_case_3.txt --h test_case_3_heuristic.txt --check-optimistic 
Execution failed with error:
Traceback (most recent call last):
  File "C:\Users\Mateo\AppData\Local\Temp\tmpga3kpq40\lab1py\solution.py", line 241, in <module>
    main()
  File "C:\Users\Mateo\AppData\Local\Temp\tmpga3kpq40\lab1py\solution.py", line 191, in main
    optimistic = sys.argv[i+1]
                 ~~~~~~~~^^^^^
IndexError: list index out of range


- Failed test: HEURISTIC-OPTIMISTIC test_case_3_heuristic_nonopt.txt
- Command run: python solution.py --ss test_case_3.txt --h test_case_3_heuristic_nonopt.txt --check-optimistic 
Execution failed with error:
Traceback (most recent call last):
  File "C:\Users\Mateo\AppData\Local\Temp\tmpga3kpq40\lab1py\solution.py", line 241, in <module>
    main()
  File "C:\Users\Mateo\AppData\Local\Temp\tmpga3kpq40\lab1py\solution.py", line 191, in main
    optimistic = sys.argv[i+1]
                 ~~~~~~~~^^^^^
IndexError: list index out of range


=== TOTAL RESULTS ===
18 / 39 tests passed. (46.15%)

